<?xml version="1.0" ?>
<!-- =================================================================================== -->
<!-- |    This document was autogenerated by xacro from alpha.xacro                    | -->
<!-- |    EDITING THIS FILE BY HAND IS NOT RECOMMENDED                                 | -->
<!-- =================================================================================== -->
<robot name="alpha" xmlns:xacro="http://ros.org/wiki/xacro">
  <!-- Defining the colors used in this robot -->
  <material name="Black">
    <color rgba="0 0 0 1"/>
  </material>
  <material name="White">
    <color rgba="1 1 1 1"/>
  </material>
  <material name="Blue">
    <color rgba="0 0 1 1"/>
  </material>
  <material name="Red">
    <color rgba="1 0 0 1"/>
  </material>
  <!-- base link -->
  <link name="base_link">
    <visual>
      <origin rpy="0 0 0" xyz="0 0 0.085"/>
      <geometry>
        <cylinder length="0.05" radius="0.15"/>
      </geometry>
      <material name="White"/>
    </visual>
    <collision>
      <origin rpy="0 0 0" xyz="0 0 0.095"/>
      <geometry>
        <cylinder length="0.05" radius="0.15"/>
      </geometry>
    </collision>
    <inertial>
      <mass value="1"/>
      <inertia ixx="1.0" ixy="0.0" ixz="0.0" iyy="0.5" iyz="0.0" izz="1.0"/>
    </inertial>
  </link>
  <link name="motor_-1">
    <visual>
      <origin rpy="0 0 0" xyz="0 0 -0.01"/>
      <geometry>
        <box size="0.05 0.02 0.02"/>
      </geometry>
      <material name="Red"/>
    </visual>
    <collision>
      <origin rpy="0 0 0" xyz="0 0 -0.01"/>
      <geometry>
        <box size="0.05 0.02 0.02"/>
      </geometry>
    </collision>
    <inertial>
      <mass value="1"/>
      <inertia ixx="1.0" ixy="0.0" ixz="0.0" iyy="0.5" iyz="0.0" izz="1.0"/>
    </inertial>
  </link>
  <joint name="joint_motor_-1" type="fixed">
    <parent link="base_link"/>
    <child link="motor_-1"/>
    <origin rpy="0 0 0" xyz="0 -0.125 0.025"/>
  </joint>
  <link name="motor_1">
    <visual>
      <origin rpy="0 0 0" xyz="0 0 -0.01"/>
      <geometry>
        <box size="0.05 0.02 0.02"/>
      </geometry>
      <material name="Red"/>
    </visual>
    <collision>
      <origin rpy="0 0 0" xyz="0 0 -0.01"/>
      <geometry>
        <box size="0.05 0.02 0.02"/>
      </geometry>
    </collision>
    <inertial>
      <mass value="1"/>
      <inertia ixx="1.0" ixy="0.0" ixz="0.0" iyy="0.5" iyz="0.0" izz="1.0"/>
    </inertial>
  </link>
  <joint name="joint_motor_1" type="fixed">
    <parent link="base_link"/>
    <child link="motor_1"/>
    <origin rpy="0 0 0" xyz="0 0.125 0.025"/>
  </joint>
  <link name="wheel_-1">
    <visual>
      <origin rpy="1.570795 0 0" xyz="0 -0.005 0"/>
      <geometry>
        <cylinder length="0.01" radius="0.05"/>
      </geometry>
      <material name="Blue"/>
    </visual>
    <collision>
      <origin rpy="1.570795 0 0" xyz="0 -0.005 0"/>
      <geometry>
        <cylinder length="0.01" radius="0.05"/>
      </geometry>
    </collision>
    <inertial>
      <mass value="1"/>
      <inertia ixx="1.0" ixy="0.0" ixz="0.0" iyy="0.5" iyz="0.0" izz="1.0"/>
    </inertial>
  </link>
  <joint name="joint_wheel_-1" type="continuous">
    <parent link="motor_-1"/>
    <child link="wheel_-1"/>
    <origin rpy="0 0 0" xyz="0 -0.025 -0.01"/>
    <axis xyz="0 1 0"/>
  </joint>
  <link name="wheel_1">
    <visual>
      <origin rpy="1.570795 0 0" xyz="0 0.005 0"/>
      <geometry>
        <cylinder length="0.01" radius="0.05"/>
      </geometry>
      <material name="Blue"/>
    </visual>
    <collision>
      <origin rpy="1.570795 0 0" xyz="0 0.005 0"/>
      <geometry>
        <cylinder length="0.01" radius="0.05"/>
      </geometry>
    </collision>
    <inertial>
      <mass value="1"/>
      <inertia ixx="1.0" ixy="0.0" ixz="0.0" iyy="0.5" iyz="0.0" izz="1.0"/>
    </inertial>
  </link>
  <joint name="joint_wheel_1" type="continuous">
    <parent link="motor_1"/>
    <child link="wheel_1"/>
    <origin rpy="0 0 0" xyz="0 0.025 -0.01"/>
    <axis xyz="0 -1 0"/>
  </joint>
  <link name="link_1">
    <visual>
      <origin rpy="0 0 0" xyz="0 0 0.05"/>
      <geometry>
        <cylinder length="0.1" radius="0.03"/>
      </geometry>
      <material name="Red"/>
    </visual>
    <collision>
      <origin rpy="0 0 0" xyz="0 0 0.05"/>
      <geometry>
        <cylinder length="0.1" radius="0.03"/>
      </geometry>
    </collision>
    <inertial>
      <mass value="1"/>
      <inertia ixx="1.0" ixy="0.0" ixz="0.0" iyy="0.5" iyz="0.0" izz="1.0"/>
    </inertial>
  </link>
  <joint name="joint_1" type="revolute">
    <parent link="base_link"/>
    <child link="link_1"/>
    <origin rpy="0 0 0" xyz="0 0 z_loc"/>
    <axis xyz="axis_x axis_y axis_z"/>
    <limit effort="300" lower="-2.35" upper="2.35" velocity="1"/>
    <dynamics damping="50" friction="1"/>
  </joint>
  <link name="link_2">
    <visual>
      <origin rpy="0 0 0" xyz="0 0 0.07"/>
      <geometry>
        <cylinder length="0.14" radius="0.03"/>
      </geometry>
      <material name="Blue"/>
    </visual>
    <collision>
      <origin rpy="0 0 0" xyz="0 0 0.07"/>
      <geometry>
        <cylinder length="0.14" radius="0.03"/>
      </geometry>
    </collision>
    <inertial>
      <mass value="1"/>
      <inertia ixx="1.0" ixy="0.0" ixz="0.0" iyy="0.5" iyz="0.0" izz="1.0"/>
    </inertial>
  </link>
  <joint name="joint_2" type="revolute">
    <parent link="link_1"/>
    <child link="link_2"/>
    <origin rpy="0 0 0" xyz="0 0 z_loc"/>
    <axis xyz="axis_x axis_y axis_z"/>
    <limit effort="300" lower="-2.35" upper="2.35" velocity="1"/>
    <dynamics damping="50" friction="1"/>
  </joint>
  <link name="link_3">
    <visual>
      <origin rpy="0 0 0" xyz="0 0 0.11"/>
      <geometry>
        <cylinder length="0.22" radius="0.03"/>
      </geometry>
      <material name="Black"/>
    </visual>
    <collision>
      <origin rpy="0 0 0" xyz="0 0 0.11"/>
      <geometry>
        <cylinder length="0.22" radius="0.03"/>
      </geometry>
    </collision>
    <inertial>
      <mass value="1"/>
      <inertia ixx="1.0" ixy="0.0" ixz="0.0" iyy="0.5" iyz="0.0" izz="1.0"/>
    </inertial>
  </link>
  <joint name="joint_3" type="revolute">
    <parent link="link_2"/>
    <child link="link_3"/>
    <origin rpy="0 0 0" xyz="0 0 z_loc"/>
    <axis xyz="axis_x axis_y axis_z"/>
    <limit effort="300" lower="-2.35" upper="2.35" velocity="1"/>
    <dynamics damping="50" friction="1"/>
  </joint>
  <!-- Gripper link and joint -->
  <link name="gripper_finger_link1">
    <visual>
      <origin xyz="0.04 -0.03 0"/>
      <geometry>
        <box size="0.08 0.01 0.01"/>
      </geometry>
      <material name="White"/>
    </visual>
    <inertial>
      <mass value="1"/>
      <inertia ixx="1.0" ixy="0.0" ixz="0.0" iyy="0.5" iyz="0.0" izz="1.0"/>
    </inertial>
  </link>
  <link name="gripper_finger_link2">
    <visual>
      <origin xyz="0.04 -0.03 0"/>
      <geometry>
        <box size="0.08 0.01 0.01"/>
      </geometry>
      <material name="White"/>
    </visual>
    <inertial>
      <mass value="1"/>
      <inertia ixx="1.0" ixy="0.0" ixz="0.0" iyy="0.5" iyz="0.0" izz="1.0"/>
    </inertial>
  </link>
  <joint name="finger_joint1" type="prismatic">
    <parent link="link3"/>
    <child link="gripper_finger_link1"/>
    <origin xyz="0.0 0 0.22"/>
    <axis xyz="0 1 0"/>
    <limit effort="100" lower="0" upper="0.06" velocity="1.0"/>
    <dynamics damping="50" friction="1"/>
  </joint>
  <joint name="finger_joint2" type="fixed">
    <parent link="link_3"/>
    <child link="gripper_finger_link2"/>
    <origin xyz="0.0 0 0.22"/>
  </joint>
  <!-- Grasping frame -->
  <link name="grasping_frame"/>
  <joint name="grasping_frame_joint" type="fixed">
    <parent link="link6"/>
    <child link="grasping_frame"/>
    <origin rpy="0 0 0" xyz="0.08 0 0"/>
  </joint>
  <!-- ////////////   Gazebo   //////////// -->
  <gazebo reference="base_link">
    <material>Gazebo/White</material>
  </gazebo>
  <gazebo reference="link1">
    <material>Gazebo/Blue</material>
  </gazebo>
  <gazebo reference="link2">
    <material>Gazebo/White</material>
  </gazebo>
  <gazebo reference="link3">
    <material>Gazebo/Blue</material>
  </gazebo>
  <gazebo reference="motor_1">
    <material>Gazebo/Black</material>
  </gazebo>
  <gazebo reference="motor_-1">
    <material>Gazebo/Black</material>
  </gazebo>
  <gazebo reference="wheel_1">
    <material>Gazebo/Blue</material>
  </gazebo>
  <gazebo reference="wheel_-1">
    <material>Gazebo/Blue</material>
  </gazebo>
  <gazebo reference="gripper_finger_link1">
    <material>Gazebo/White</material>
  </gazebo>
  <gazebo reference="gripper_finger_link2">
    <material>Gazebo/White</material>
  </gazebo>
  <transmission name="tran1">
    <type>transmission_interface/SimpleTransmission</type>
    <joint name="joint_1">
      <hardwareInterface>hardware_interface/PositionJointInterface</hardwareInterface>
    </joint>
    <actuator name="motor1">
      <hardwareInterface>hardware_interface/PositionJointInterface</hardwareInterface>
      <mechanicalReduction>1</mechanicalReduction>
    </actuator>
  </transmission>
  <transmission name="tran1">
    <type>transmission_interface/SimpleTransmission</type>
    <joint name="joint_2">
      <hardwareInterface>hardware_interface/PositionJointInterface</hardwareInterface>
    </joint>
    <actuator name="motor1">
      <hardwareInterface>hardware_interface/PositionJointInterface</hardwareInterface>
      <mechanicalReduction>1</mechanicalReduction>
    </actuator>
  </transmission>
  <transmission name="tran1">
    <type>transmission_interface/SimpleTransmission</type>
    <joint name="joint_3">
      <hardwareInterface>hardware_interface/PositionJointInterface</hardwareInterface>
    </joint>
    <actuator name="motor1">
      <hardwareInterface>hardware_interface/PositionJointInterface</hardwareInterface>
      <mechanicalReduction>1</mechanicalReduction>
    </actuator>
  </transmission>
  <transmission name="tran1">
    <type>transmission_interface/SimpleTransmission</type>
    <joint name="joint_motor_-1">
      <hardwareInterface>hardware_interface/PositionJointInterface</hardwareInterface>
    </joint>
    <actuator name="motor1">
      <hardwareInterface>hardware_interface/PositionJointInterface</hardwareInterface>
      <mechanicalReduction>1</mechanicalReduction>
    </actuator>
  </transmission>
  <transmission name="tran1">
    <type>transmission_interface/SimpleTransmission</type>
    <joint name="joint_motor_1">
      <hardwareInterface>hardware_interface/PositionJointInterface</hardwareInterface>
    </joint>
    <actuator name="motor1">
      <hardwareInterface>hardware_interface/PositionJointInterface</hardwareInterface>
      <mechanicalReduction>1</mechanicalReduction>
    </actuator>
  </transmission>
  <transmission name="tran1">
    <type>transmission_interface/SimpleTransmission</type>
    <joint name="joint_wheel_1">
      <hardwareInterface>hardware_interface/PositionJointInterface</hardwareInterface>
    </joint>
    <actuator name="motor1">
      <hardwareInterface>hardware_interface/PositionJointInterface</hardwareInterface>
      <mechanicalReduction>1</mechanicalReduction>
    </actuator>
  </transmission>
  <transmission name="tran1">
    <type>transmission_interface/SimpleTransmission</type>
    <joint name="joint_wheel_-1">
      <hardwareInterface>hardware_interface/PositionJointInterface</hardwareInterface>
    </joint>
    <actuator name="motor1">
      <hardwareInterface>hardware_interface/PositionJointInterface</hardwareInterface>
      <mechanicalReduction>1</mechanicalReduction>
    </actuator>
  </transmission>
  <transmission name="tran1">
    <type>transmission_interface/SimpleTransmission</type>
    <joint name="finger_joint1">
      <hardwareInterface>hardware_interface/PositionJointInterface</hardwareInterface>
    </joint>
    <actuator name="motor1">
      <hardwareInterface>hardware_interface/PositionJointInterface</hardwareInterface>
      <mechanicalReduction>1</mechanicalReduction>
    </actuator>
  </transmission>
  <transmission name="tran1">
    <type>transmission_interface/SimpleTransmission</type>
    <joint name="joint_wheel_1"/>
    <actuator name="motor_1">
      <hardwareInterface>hardware_interface/VelocityJointInterface</hardwareInterface>
      <mechanicalReduction>1</mechanicalReduction>
    </actuator>
  </transmission>
  <transmission name="tran1">
    <type>transmission_interface/SimpleTransmission</type>
    <joint name="joint_wheel_-1"/>
    <actuator name="motor_-1">
      <hardwareInterface>hardware_interface/VelocityJointInterface</hardwareInterface>
      <mechanicalReduction>1</mechanicalReduction>
    </actuator>
  </transmission>
  <!-- ros_control plugin -->
  <!-->
    <gazebo>
        <plugin name="differential_drive_controller" filename="libgazebo_ros_diff_drive.so">
            <rosDebugLevel>Debug</rosDebugLevel>
            <publishWheelTF>true</publishWheelTF>
            <robotNamespace>/</robotNamespace>
            <publishTf>1</publishTf>
            <publishWheelJointState>true</publishWheelJointState>
            <alwaysOn>true</alwaysOn>
            <updateRate>100.0</updateRate>
            <legacyMode>true</legacyMode>
            <leftJoint>joint_wheel_-1</leftJoint>
            <rightJoint>joint_wheel_1</rightJoint>
            <wheelSeparation>${base_radius*2}</wheelSeparation>
            <wheelDiameter>${2*wheel_radius}</wheelDiameter>
            <broadcastTF>1</broadcastTF>
            <wheelTorque>30</wheelTorque>
            <wheelAcceleration>1.8</wheelAcceleration>
            <commandTopic>cmd_vel</commandTopic>
            <odometryFrame>odom</odometryFrame> 
            <odometryTopic>odom</odometryTopic> 
            <robotBaseFrame>base_footprint</robotBaseFrame>
        </plugin>
    </gazebo> 
<-->
  <gazebo>
    <plugin filename="libgazebo_ros_control.so" name="gazebo_ros_control">
      <robotNamespace>/Alpha</robotNamespace>
    </plugin>
  </gazebo>
</robot>

